2024-06-19 23:35:27,442 - ERROR - collect_brand_goods_detail,An error occurred: 1 validation error for CollectionRecordsModel
end_date
  Input should be a valid string [type=string_type, input_value=None, input_type=NoneType]
    For further information visit https://errors.pydantic.dev/2.7/v/string_type
Traceback (most recent call last):
  File "C:\Users\user\Desktop\Project_Scraper\app\routers\collect.py", line 302, in send_goods_detail
    record = CollectionRecordsModel(**message_body)
             ^^^^^^^^^^^^^^^^^^^^^^^^^^^^^^^^^^^^^^
  File "C:\Users\user\Desktop\Project_Scraper\venv\Lib\site-packages\odmantic\model.py", line 542, in __init__
    super().__init__(**data)
  File "C:\Users\user\Desktop\Project_Scraper\venv\Lib\site-packages\pydantic\main.py", line 176, in __init__
    self.__pydantic_validator__.validate_python(data, self_instance=self)
pydantic_core._pydantic_core.ValidationError: 1 validation error for CollectionRecordsModel
end_date
  Input should be a valid string [type=string_type, input_value=None, input_type=NoneType]
    For further information visit https://errors.pydantic.dev/2.7/v/string_type
2024-06-19 23:38:47,935 - ERROR - Record with id 6672ed77ecb539ef4bfd8644 not found
2024-06-19 23:51:24,069 - ERROR - Record with id 6672f06cf934faf2c4900cb5 not found
